<?xml version="1.0" encoding="UTF-8"?>
<robot xmlns:xacro="http://ros.org/wiki/xacro">    		 
   <xacro:include filename="$(find omnirob_robin_description)/urdf/omnirob_robin_base/base.transmission.xacro" />
   <xacro:macro name="base" params="">
      <link name="world" />
      <joint name="odom_joint" type="fixed">
         <parent link="world" />
         <child link="odom" />
      </joint>
      <link name="odom">
         <inertial>
            <mass value="1" />
            <origin xyz="0.0 0.0 0.0" rpy="0 0 0" />
            <inertia ixx="0.1" ixy="0.0" ixz="0.0" iyy="0.1" iyz="0.0" izz="0.1" />
         </inertial>
      </link>
      <joint name="base_x_joint" type="prismatic">
         <origin xyz="0 0 0" rpy="0 0 0" />
         <axis xyz="1 0 0" />
         <dynamics damping="0.0" friction="0.0" />
         <calibration rising="0.0" falling="0.0" />
         <limit effort="10" velocity="1.0" lower="-100" upper="100" />
         <parent link="odom" />
         <child link="base_x_link" />
      </joint>
      <link name="base_x_link">
         <inertial>
            <mass value="1" />
            <origin xyz="0 0 0.0" />
            <inertia ixx="0.1" ixy="0.0" ixz="0.0" iyy="0.1" iyz="0.0" izz="0.1" />
         </inertial>
      </link>
      <joint name="base_y_joint" type="prismatic">
         <origin xyz="0 0 0" rpy="0 0 0" />
         <axis xyz="0 1 0" />
         <dynamics damping="0.0" friction="0.0" />
         <limit effort="10" velocity="1.0" lower="-100" upper="100" />
         <parent link="base_x_link" />
         <child link="base_y_link" />
      </joint>
      <link name="base_y_link">
         <inertial>
            <mass value="1" />
            <origin xyz="0.0 0.0 0.0" rpy="0 0 0" />
            <inertia ixx="0.1" ixy="0.0" ixz="0.0" iyy="0.1" iyz="0.0" izz="0.1" />
         </inertial>
      </link>
      <joint name="base_yaw_joint" type="continuous">
         <origin xyz="0 0 0" rpy="0 0 0" />
         <axis xyz="0 0 1" />
         <dynamics damping="0.0" friction="0.0" />
         <limit effort="10" velocity="1.0" lower="-100" upper="100"/>
         <parent link="base_y_link" />
         <child link="base_link" />
      </joint>
      <link name="base_link">
         <inertial>
            <mass value="1.0" />
            <origin xyz="0.0 0.0 0.0" rpy="0 0 0" />
            <inertia ixx="0.1" ixy="0.0" ixz="0.0" iyy="0.1" iyz="0.0" izz="0.1" />
         </inertial>
         <!-- z verschiebung = Abstand von Boden zu Motor achse + Rad Radius -->
         <visual>
            <origin xyz="0 0 0" rpy="1.57079 0 1.57079" />
            <geometry>
               <mesh filename="package://omnirob_robin_description/meshes/omnirob.dae" scale="0.001 0.001 0.001" />
            </geometry>
            <material name="test">
               <color rgba="0.5 0.5 0.5 1.0" />
            </material>
         </visual>
         <collision>
            <origin xyz="0.0 0.0 0.36" rpy="0 0 0" />
            <geometry>
               <cylinder length="0.71" radius="0.425" />
            </geometry>
         </collision>
      </link>
      <joint name="base_mass_joint" type="fixed">
         <origin xyz="0 0 0.4" rpy="0 0 0" />
         <parent link="base_link" />
         <child link="base_mass_link" />
      </joint>
      <link name="base_mass_link">
         <inertial>
            <mass value="80.0" />
            <origin xyz="0.0 0.0 0.0" rpy="0 0 0" />
            <inertia ixx="0.5" ixy="0.0" ixz="0.0" iyy="0.5" iyz="0.0" izz="0.5" />
         </inertial>
      </link>
      <xacro:if value="${simulated}">
         <xacro:omnirob_transmission />         
      </xacro:if>
   </xacro:macro>
</robot>

